[2023-11-25T03:55:21.007+0000] {taskinstance.py:1159} INFO - Dependencies all met for dep_context=non-requeueable deps ti=<TaskInstance: dag_extract_despesas.task_load_despesas manual__2023-11-24T20:37:03.276901+00:00 [queued]>
[2023-11-25T03:55:21.015+0000] {taskinstance.py:1159} INFO - Dependencies all met for dep_context=requeueable deps ti=<TaskInstance: dag_extract_despesas.task_load_despesas manual__2023-11-24T20:37:03.276901+00:00 [queued]>
[2023-11-25T03:55:21.015+0000] {taskinstance.py:1361} INFO - Starting attempt 8 of 11
[2023-11-25T03:55:21.047+0000] {taskinstance.py:1382} INFO - Executing <Task(PythonOperator): task_load_despesas> on 2023-11-24 20:37:03.276901+00:00
[2023-11-25T03:55:21.055+0000] {standard_task_runner.py:57} INFO - Started process 357 to run task
[2023-11-25T03:55:21.058+0000] {standard_task_runner.py:84} INFO - Running: ['***', 'tasks', 'run', 'dag_extract_despesas', 'task_load_despesas', 'manual__2023-11-24T20:37:03.276901+00:00', '--job-id', '195', '--raw', '--subdir', 'DAGS_FOLDER/dag_extract_despesas.py', '--cfg-path', '/tmp/tmp6ol_gny_']
[2023-11-25T03:55:21.059+0000] {standard_task_runner.py:85} INFO - Job 195: Subtask task_load_despesas
[2023-11-25T03:55:21.102+0000] {task_command.py:416} INFO - Running <TaskInstance: dag_extract_despesas.task_load_despesas manual__2023-11-24T20:37:03.276901+00:00 [running]> on host 65d7bc470c88
[2023-11-25T03:55:21.167+0000] {taskinstance.py:1662} INFO - Exporting env vars: AIRFLOW_CTX_DAG_OWNER='***' AIRFLOW_CTX_DAG_ID='dag_extract_despesas' AIRFLOW_CTX_TASK_ID='task_load_despesas' AIRFLOW_CTX_EXECUTION_DATE='2023-11-24T20:37:03.276901+00:00' AIRFLOW_CTX_TRY_NUMBER='8' AIRFLOW_CTX_DAG_RUN_ID='manual__2023-11-24T20:37:03.276901+00:00'
[2023-11-25T03:55:24.308+0000] {taskinstance.py:1937} ERROR - Task failed with exception
Traceback (most recent call last):
  File "/home/airflow/.local/lib/python3.8/site-packages/airflow/operators/python.py", line 192, in execute
    return_value = self.execute_callable()
  File "/home/airflow/.local/lib/python3.8/site-packages/airflow/operators/python.py", line 209, in execute_callable
    return self.python_callable(*self.op_args, **self.op_kwargs)
  File "/opt/airflow/dags/scripts/etl.py", line 274, in loadDespesasFinal
    df = pl.read_parquet(temp_file_name)
  File "/home/airflow/.local/lib/python3.8/site-packages/polars/io/parquet/functions.py", line 131, in read_parquet
    return pl.DataFrame._read_parquet(
  File "/home/airflow/.local/lib/python3.8/site-packages/polars/dataframe/frame.py", line 862, in _read_parquet
    self._df = PyDataFrame.read_parquet(
FileNotFoundError: No such file or directory (os error 2): /tmp/tmpjehdb4ih
[2023-11-25T03:55:24.329+0000] {taskinstance.py:1400} INFO - Marking task as UP_FOR_RETRY. dag_id=dag_extract_despesas, task_id=task_load_despesas, execution_date=20231124T203703, start_date=20231125T035521, end_date=20231125T035524
[2023-11-25T03:55:24.379+0000] {standard_task_runner.py:104} ERROR - Failed to execute job 195 for task task_load_despesas (No such file or directory (os error 2): /tmp/tmpjehdb4ih; 357)
[2023-11-25T03:55:24.416+0000] {local_task_job_runner.py:228} INFO - Task exited with return code 1
[2023-11-25T03:55:24.438+0000] {taskinstance.py:2778} INFO - 0 downstream tasks scheduled from follow-on schedule check
