[2023-11-24T15:44:29.653+0000] {taskinstance.py:1159} INFO - Dependencies all met for dep_context=non-requeueable deps ti=<TaskInstance: dag_extract_despesas.task_extract_despesas manual__2023-11-24T15:42:14.955775+00:00 [queued]>
[2023-11-24T15:44:29.662+0000] {taskinstance.py:1159} INFO - Dependencies all met for dep_context=requeueable deps ti=<TaskInstance: dag_extract_despesas.task_extract_despesas manual__2023-11-24T15:42:14.955775+00:00 [queued]>
[2023-11-24T15:44:29.663+0000] {taskinstance.py:1361} INFO - Starting attempt 2 of 5
[2023-11-24T15:44:29.679+0000] {taskinstance.py:1382} INFO - Executing <Task(PythonOperator): task_extract_despesas> on 2023-11-24 15:42:14.955775+00:00
[2023-11-24T15:44:29.685+0000] {standard_task_runner.py:57} INFO - Started process 376 to run task
[2023-11-24T15:44:29.688+0000] {standard_task_runner.py:84} INFO - Running: ['***', 'tasks', 'run', 'dag_extract_despesas', 'task_extract_despesas', 'manual__2023-11-24T15:42:14.955775+00:00', '--job-id', '31', '--raw', '--subdir', 'DAGS_FOLDER/dag_extract_despesas.py', '--cfg-path', '/tmp/tmpwbloea7y']
[2023-11-24T15:44:29.689+0000] {standard_task_runner.py:85} INFO - Job 31: Subtask task_extract_despesas
[2023-11-24T15:44:29.738+0000] {task_command.py:416} INFO - Running <TaskInstance: dag_extract_despesas.task_extract_despesas manual__2023-11-24T15:42:14.955775+00:00 [running]> on host eea2b93d502c
[2023-11-24T15:44:29.812+0000] {taskinstance.py:1662} INFO - Exporting env vars: AIRFLOW_CTX_DAG_OWNER='***' AIRFLOW_CTX_DAG_ID='dag_extract_despesas' AIRFLOW_CTX_TASK_ID='task_extract_despesas' AIRFLOW_CTX_EXECUTION_DATE='2023-11-24T15:42:14.955775+00:00' AIRFLOW_CTX_TRY_NUMBER='2' AIRFLOW_CTX_DAG_RUN_ID='manual__2023-11-24T15:42:14.955775+00:00'
[2023-11-24T15:44:29.837+0000] {taskinstance.py:1937} ERROR - Task failed with exception
Traceback (most recent call last):
  File "/home/airflow/.local/lib/python3.8/site-packages/polars/io/database.py", line 725, in _read_sql_connectorx
    tbl = cx.read_sql(
  File "/home/airflow/.local/lib/python3.8/site-packages/connectorx/__init__.py", line 297, in read_sql
    result = _read_sql(
RuntimeError: db error: ERROR: relation "deputados" does not exist

The above exception was the direct cause of the following exception:

Traceback (most recent call last):
  File "/home/airflow/.local/lib/python3.8/site-packages/airflow/operators/python.py", line 192, in execute
    return_value = self.execute_callable()
  File "/home/airflow/.local/lib/python3.8/site-packages/airflow/operators/python.py", line 209, in execute_callable
    return self.python_callable(*self.op_args, **self.op_kwargs)
  File "/opt/airflow/dags/scripts/get_despesas_stg.py", line 97, in extractDespesas
    ids = pl.read_database_uri('SELECT "id" from deputados', path_db).to_series().to_list()
  File "/home/airflow/.local/lib/python3.8/site-packages/polars/io/database.py", line 689, in read_database_uri
    return _read_sql_connectorx(
  File "/home/airflow/.local/lib/python3.8/site-packages/polars/io/database.py", line 737, in _read_sql_connectorx
    raise type(err)(errmsg) from err
RuntimeError: db error: ERROR: relation "deputados" does not exist
[2023-11-24T15:44:29.857+0000] {taskinstance.py:1400} INFO - Marking task as UP_FOR_RETRY. dag_id=dag_extract_despesas, task_id=task_extract_despesas, execution_date=20231124T154214, start_date=20231124T154429, end_date=20231124T154429
[2023-11-24T15:44:29.876+0000] {standard_task_runner.py:104} ERROR - Failed to execute job 31 for task task_extract_despesas (db error: ERROR: relation "deputados" does not exist; 376)
[2023-11-24T15:44:29.901+0000] {local_task_job_runner.py:228} INFO - Task exited with return code 1
[2023-11-24T15:44:29.927+0000] {taskinstance.py:2778} INFO - 0 downstream tasks scheduled from follow-on schedule check
