[2023-11-25T03:42:22.868+0000] {taskinstance.py:1159} INFO - Dependencies all met for dep_context=non-requeueable deps ti=<TaskInstance: dag_extract_despesas.task_load_despesas scheduled__2023-11-24T20:26:32.148764+00:00 [queued]>
[2023-11-25T03:42:22.880+0000] {taskinstance.py:1159} INFO - Dependencies all met for dep_context=requeueable deps ti=<TaskInstance: dag_extract_despesas.task_load_despesas scheduled__2023-11-24T20:26:32.148764+00:00 [queued]>
[2023-11-25T03:42:22.881+0000] {taskinstance.py:1361} INFO - Starting attempt 4 of 4
[2023-11-25T03:42:22.905+0000] {taskinstance.py:1382} INFO - Executing <Task(PythonOperator): task_load_despesas> on 2023-11-24 20:26:32.148764+00:00
[2023-11-25T03:42:22.911+0000] {standard_task_runner.py:57} INFO - Started process 85 to run task
[2023-11-25T03:42:22.915+0000] {standard_task_runner.py:84} INFO - Running: ['***', 'tasks', 'run', 'dag_extract_despesas', 'task_load_despesas', 'scheduled__2023-11-24T20:26:32.148764+00:00', '--job-id', '186', '--raw', '--subdir', 'DAGS_FOLDER/dag_extract_despesas.py', '--cfg-path', '/tmp/tmpoojfe7a3']
[2023-11-25T03:42:22.918+0000] {standard_task_runner.py:85} INFO - Job 186: Subtask task_load_despesas
[2023-11-25T03:42:23.078+0000] {task_command.py:416} INFO - Running <TaskInstance: dag_extract_despesas.task_load_despesas scheduled__2023-11-24T20:26:32.148764+00:00 [running]> on host 65d7bc470c88
[2023-11-25T03:42:23.259+0000] {taskinstance.py:1662} INFO - Exporting env vars: AIRFLOW_CTX_DAG_OWNER='***' AIRFLOW_CTX_DAG_ID='dag_extract_despesas' AIRFLOW_CTX_TASK_ID='task_load_despesas' AIRFLOW_CTX_EXECUTION_DATE='2023-11-24T20:26:32.148764+00:00' AIRFLOW_CTX_TRY_NUMBER='4' AIRFLOW_CTX_DAG_RUN_ID='scheduled__2023-11-24T20:26:32.148764+00:00'
[2023-11-25T03:42:26.314+0000] {taskinstance.py:1937} ERROR - Task failed with exception
Traceback (most recent call last):
  File "/home/airflow/.local/lib/python3.8/site-packages/airflow/operators/python.py", line 192, in execute
    return_value = self.execute_callable()
  File "/home/airflow/.local/lib/python3.8/site-packages/airflow/operators/python.py", line 209, in execute_callable
    return self.python_callable(*self.op_args, **self.op_kwargs)
  File "/opt/airflow/dags/scripts/etl.py", line 274, in loadDespesasFinal
    df = pl.read_parquet(temp_file_name)
  File "/home/airflow/.local/lib/python3.8/site-packages/polars/io/parquet/functions.py", line 131, in read_parquet
    return pl.DataFrame._read_parquet(
  File "/home/airflow/.local/lib/python3.8/site-packages/polars/dataframe/frame.py", line 862, in _read_parquet
    self._df = PyDataFrame.read_parquet(
FileNotFoundError: No such file or directory (os error 2): /tmp/tmpws86nt91
[2023-11-25T03:42:26.335+0000] {taskinstance.py:1400} INFO - Marking task as FAILED. dag_id=dag_extract_despesas, task_id=task_load_despesas, execution_date=20231124T202632, start_date=20231125T034222, end_date=20231125T034226
[2023-11-25T03:42:26.352+0000] {standard_task_runner.py:104} ERROR - Failed to execute job 186 for task task_load_despesas (No such file or directory (os error 2): /tmp/tmpws86nt91; 85)
[2023-11-25T03:42:26.384+0000] {local_task_job_runner.py:228} INFO - Task exited with return code 1
[2023-11-25T03:42:26.402+0000] {taskinstance.py:2778} INFO - 0 downstream tasks scheduled from follow-on schedule check
