[2023-11-24T15:49:20.993+0000] {taskinstance.py:1159} INFO - Dependencies all met for dep_context=non-requeueable deps ti=<TaskInstance: dag_extract_despesas.task_extract_despesas manual__2023-11-24T15:46:08.577726+00:00 [queued]>
[2023-11-24T15:49:21.009+0000] {taskinstance.py:1159} INFO - Dependencies all met for dep_context=requeueable deps ti=<TaskInstance: dag_extract_despesas.task_extract_despesas manual__2023-11-24T15:46:08.577726+00:00 [queued]>
[2023-11-24T15:49:21.010+0000] {taskinstance.py:1361} INFO - Starting attempt 4 of 4
[2023-11-24T15:49:21.036+0000] {taskinstance.py:1382} INFO - Executing <Task(PythonOperator): task_extract_despesas> on 2023-11-24 15:46:08.577726+00:00
[2023-11-24T15:49:21.044+0000] {standard_task_runner.py:57} INFO - Started process 500 to run task
[2023-11-24T15:49:21.049+0000] {standard_task_runner.py:84} INFO - Running: ['***', 'tasks', 'run', 'dag_extract_despesas', 'task_extract_despesas', 'manual__2023-11-24T15:46:08.577726+00:00', '--job-id', '39', '--raw', '--subdir', 'DAGS_FOLDER/dag_extract_despesas.py', '--cfg-path', '/tmp/tmpz3_cqk6c']
[2023-11-24T15:49:21.052+0000] {standard_task_runner.py:85} INFO - Job 39: Subtask task_extract_despesas
[2023-11-24T15:49:21.156+0000] {task_command.py:416} INFO - Running <TaskInstance: dag_extract_despesas.task_extract_despesas manual__2023-11-24T15:46:08.577726+00:00 [running]> on host eea2b93d502c
[2023-11-24T15:49:21.309+0000] {taskinstance.py:1662} INFO - Exporting env vars: AIRFLOW_CTX_DAG_OWNER='***' AIRFLOW_CTX_DAG_ID='dag_extract_despesas' AIRFLOW_CTX_TASK_ID='task_extract_despesas' AIRFLOW_CTX_EXECUTION_DATE='2023-11-24T15:46:08.577726+00:00' AIRFLOW_CTX_TRY_NUMBER='4' AIRFLOW_CTX_DAG_RUN_ID='manual__2023-11-24T15:46:08.577726+00:00'
[2023-11-24T15:49:21.413+0000] {taskinstance.py:1937} ERROR - Task failed with exception
Traceback (most recent call last):
  File "/home/airflow/.local/lib/python3.8/site-packages/polars/io/database.py", line 725, in _read_sql_connectorx
    tbl = cx.read_sql(
  File "/home/airflow/.local/lib/python3.8/site-packages/connectorx/__init__.py", line 297, in read_sql
    result = _read_sql(
RuntimeError: db error: ERROR: relation "deputados" does not exist

The above exception was the direct cause of the following exception:

Traceback (most recent call last):
  File "/home/airflow/.local/lib/python3.8/site-packages/airflow/operators/python.py", line 192, in execute
    return_value = self.execute_callable()
  File "/home/airflow/.local/lib/python3.8/site-packages/airflow/operators/python.py", line 209, in execute_callable
    return self.python_callable(*self.op_args, **self.op_kwargs)
  File "/opt/airflow/dags/scripts/get_despesas_stg.py", line 97, in extractDespesas
    ids = pl.read_database_uri('SELECT "id" from deputados', path_db).to_series().to_list()
  File "/home/airflow/.local/lib/python3.8/site-packages/polars/io/database.py", line 689, in read_database_uri
    return _read_sql_connectorx(
  File "/home/airflow/.local/lib/python3.8/site-packages/polars/io/database.py", line 737, in _read_sql_connectorx
    raise type(err)(errmsg) from err
RuntimeError: db error: ERROR: relation "deputados" does not exist
[2023-11-24T15:49:21.441+0000] {taskinstance.py:1400} INFO - Marking task as FAILED. dag_id=dag_extract_despesas, task_id=task_extract_despesas, execution_date=20231124T154608, start_date=20231124T154920, end_date=20231124T154921
[2023-11-24T15:49:21.467+0000] {standard_task_runner.py:104} ERROR - Failed to execute job 39 for task task_extract_despesas (db error: ERROR: relation "deputados" does not exist; 500)
[2023-11-24T15:49:21.502+0000] {local_task_job_runner.py:228} INFO - Task exited with return code 1
[2023-11-24T15:49:21.544+0000] {taskinstance.py:2778} INFO - 0 downstream tasks scheduled from follow-on schedule check
